Traceback (most recent call last):
  File "/Users/carla/Documents/ITC-Tec/Ago-Dic22/SeguridadRedes_SistemasSoft/projectScss/Pagina-web/backend/manage.py", line 22, in <module>
    main()
  File "/Users/carla/Documents/ITC-Tec/Ago-Dic22/SeguridadRedes_SistemasSoft/projectScss/Pagina-web/backend/manage.py", line 18, in main
    execute_from_command_line(sys.argv)
  File "/Users/carla/opt/anaconda3/envs/DjangoEnv_PAS/lib/python3.9/site-packages/django/core/management/__init__.py", line 446, in execute_from_command_line
    utility.execute()
  File "/Users/carla/opt/anaconda3/envs/DjangoEnv_PAS/lib/python3.9/site-packages/django/core/management/__init__.py", line 440, in execute
    self.fetch_command(subcommand).run_from_argv(self.argv)
  File "/Users/carla/opt/anaconda3/envs/DjangoEnv_PAS/lib/python3.9/site-packages/django/core/management/base.py", line 414, in run_from_argv
    self.execute(*args, **cmd_options)
  File "/Users/carla/opt/anaconda3/envs/DjangoEnv_PAS/lib/python3.9/site-packages/django/core/management/base.py", line 460, in execute
    output = self.handle(*args, **options)
  File "/Users/carla/opt/anaconda3/envs/DjangoEnv_PAS/lib/python3.9/site-packages/django_crontab/management/commands/crontab.py", line 29, in handle
    Crontab().run_job(options['jobhash'])
  File "/Users/carla/opt/anaconda3/envs/DjangoEnv_PAS/lib/python3.9/site-packages/django_crontab/crontab.py", line 126, in run_job
    job = self.__get_job_by_hash(job_hash)
  File "/Users/carla/opt/anaconda3/envs/DjangoEnv_PAS/lib/python3.9/site-packages/django_crontab/crontab.py", line 171, in __get_job_by_hash
    raise RuntimeError(
RuntimeError: No job with hash 7a60db453bdc699323c7feb3b5be04ca found. It seems the crontab is out of sync with your settings.CRONJOBS. Run "python manage.py crontab add" again to resolve this issue!
Traceback (most recent call last):
  File "/Users/carla/Documents/ITC-Tec/Ago-Dic22/SeguridadRedes_SistemasSoft/projectScss/Pagina-web/backend/manage.py", line 22, in <module>
    main()
  File "/Users/carla/Documents/ITC-Tec/Ago-Dic22/SeguridadRedes_SistemasSoft/projectScss/Pagina-web/backend/manage.py", line 18, in main
    execute_from_command_line(sys.argv)
  File "/Users/carla/opt/anaconda3/envs/DjangoEnv_PAS/lib/python3.9/site-packages/django/core/management/__init__.py", line 446, in execute_from_command_line
    utility.execute()
  File "/Users/carla/opt/anaconda3/envs/DjangoEnv_PAS/lib/python3.9/site-packages/django/core/management/__init__.py", line 440, in execute
    self.fetch_command(subcommand).run_from_argv(self.argv)
  File "/Users/carla/opt/anaconda3/envs/DjangoEnv_PAS/lib/python3.9/site-packages/django/core/management/base.py", line 414, in run_from_argv
    self.execute(*args, **cmd_options)
  File "/Users/carla/opt/anaconda3/envs/DjangoEnv_PAS/lib/python3.9/site-packages/django/core/management/base.py", line 460, in execute
    output = self.handle(*args, **options)
  File "/Users/carla/opt/anaconda3/envs/DjangoEnv_PAS/lib/python3.9/site-packages/django_crontab/management/commands/crontab.py", line 29, in handle
    Crontab().run_job(options['jobhash'])
  File "/Users/carla/opt/anaconda3/envs/DjangoEnv_PAS/lib/python3.9/site-packages/django_crontab/crontab.py", line 126, in run_job
    job = self.__get_job_by_hash(job_hash)
  File "/Users/carla/opt/anaconda3/envs/DjangoEnv_PAS/lib/python3.9/site-packages/django_crontab/crontab.py", line 171, in __get_job_by_hash
    raise RuntimeError(
RuntimeError: No job with hash 7a60db453bdc699323c7feb3b5be04ca found. It seems the crontab is out of sync with your settings.CRONJOBS. Run "python manage.py crontab add" again to resolve this issue!
Traceback (most recent call last):
  File "/Users/carla/Documents/ITC-Tec/Ago-Dic22/SeguridadRedes_SistemasSoft/projectScss/Pagina-web/backend/manage.py", line 22, in <module>
    main()
  File "/Users/carla/Documents/ITC-Tec/Ago-Dic22/SeguridadRedes_SistemasSoft/projectScss/Pagina-web/backend/manage.py", line 18, in main
    execute_from_command_line(sys.argv)
  File "/Users/carla/opt/anaconda3/envs/DjangoEnv_PAS/lib/python3.9/site-packages/django/core/management/__init__.py", line 446, in execute_from_command_line
    utility.execute()
  File "/Users/carla/opt/anaconda3/envs/DjangoEnv_PAS/lib/python3.9/site-packages/django/core/management/__init__.py", line 440, in execute
    self.fetch_command(subcommand).run_from_argv(self.argv)
  File "/Users/carla/opt/anaconda3/envs/DjangoEnv_PAS/lib/python3.9/site-packages/django/core/management/base.py", line 414, in run_from_argv
    self.execute(*args, **cmd_options)
  File "/Users/carla/opt/anaconda3/envs/DjangoEnv_PAS/lib/python3.9/site-packages/django/core/management/base.py", line 460, in execute
    output = self.handle(*args, **options)
  File "/Users/carla/opt/anaconda3/envs/DjangoEnv_PAS/lib/python3.9/site-packages/django_crontab/management/commands/crontab.py", line 29, in handle
    Crontab().run_job(options['jobhash'])
  File "/Users/carla/opt/anaconda3/envs/DjangoEnv_PAS/lib/python3.9/site-packages/django_crontab/crontab.py", line 126, in run_job
    job = self.__get_job_by_hash(job_hash)
  File "/Users/carla/opt/anaconda3/envs/DjangoEnv_PAS/lib/python3.9/site-packages/django_crontab/crontab.py", line 171, in __get_job_by_hash
    raise RuntimeError(
RuntimeError: No job with hash 7a60db453bdc699323c7feb3b5be04ca found. It seems the crontab is out of sync with your settings.CRONJOBS. Run "python manage.py crontab add" again to resolve this issue!
Traceback (most recent call last):
  File "/Users/carla/Documents/ITC-Tec/Ago-Dic22/SeguridadRedes_SistemasSoft/projectScss/Pagina-web/backend/manage.py", line 22, in <module>
    main()
  File "/Users/carla/Documents/ITC-Tec/Ago-Dic22/SeguridadRedes_SistemasSoft/projectScss/Pagina-web/backend/manage.py", line 18, in main
    execute_from_command_line(sys.argv)
  File "/Users/carla/opt/anaconda3/envs/DjangoEnv_PAS/lib/python3.9/site-packages/django/core/management/__init__.py", line 446, in execute_from_command_line
    utility.execute()
  File "/Users/carla/opt/anaconda3/envs/DjangoEnv_PAS/lib/python3.9/site-packages/django/core/management/__init__.py", line 440, in execute
    self.fetch_command(subcommand).run_from_argv(self.argv)
  File "/Users/carla/opt/anaconda3/envs/DjangoEnv_PAS/lib/python3.9/site-packages/django/core/management/base.py", line 414, in run_from_argv
    self.execute(*args, **cmd_options)
  File "/Users/carla/opt/anaconda3/envs/DjangoEnv_PAS/lib/python3.9/site-packages/django/core/management/base.py", line 460, in execute
    output = self.handle(*args, **options)
  File "/Users/carla/opt/anaconda3/envs/DjangoEnv_PAS/lib/python3.9/site-packages/django_crontab/management/commands/crontab.py", line 29, in handle
    Crontab().run_job(options['jobhash'])
  File "/Users/carla/opt/anaconda3/envs/DjangoEnv_PAS/lib/python3.9/site-packages/django_crontab/crontab.py", line 126, in run_job
    job = self.__get_job_by_hash(job_hash)
  File "/Users/carla/opt/anaconda3/envs/DjangoEnv_PAS/lib/python3.9/site-packages/django_crontab/crontab.py", line 171, in __get_job_by_hash
    raise RuntimeError(
RuntimeError: No job with hash 7a60db453bdc699323c7feb3b5be04ca found. It seems the crontab is out of sync with your settings.CRONJOBS. Run "python manage.py crontab add" again to resolve this issue!
Traceback (most recent call last):
  File "/Users/carla/Documents/ITC-Tec/Ago-Dic22/SeguridadRedes_SistemasSoft/projectScss/Pagina-web/backend/manage.py", line 22, in <module>
    main()
  File "/Users/carla/Documents/ITC-Tec/Ago-Dic22/SeguridadRedes_SistemasSoft/projectScss/Pagina-web/backend/manage.py", line 18, in main
    execute_from_command_line(sys.argv)
  File "/Users/carla/opt/anaconda3/envs/DjangoEnv_PAS/lib/python3.9/site-packages/django/core/management/__init__.py", line 446, in execute_from_command_line
    utility.execute()
  File "/Users/carla/opt/anaconda3/envs/DjangoEnv_PAS/lib/python3.9/site-packages/django/core/management/__init__.py", line 440, in execute
    self.fetch_command(subcommand).run_from_argv(self.argv)
  File "/Users/carla/opt/anaconda3/envs/DjangoEnv_PAS/lib/python3.9/site-packages/django/core/management/base.py", line 414, in run_from_argv
    self.execute(*args, **cmd_options)
  File "/Users/carla/opt/anaconda3/envs/DjangoEnv_PAS/lib/python3.9/site-packages/django/core/management/base.py", line 460, in execute
    output = self.handle(*args, **options)
  File "/Users/carla/opt/anaconda3/envs/DjangoEnv_PAS/lib/python3.9/site-packages/django_crontab/management/commands/crontab.py", line 29, in handle
    Crontab().run_job(options['jobhash'])
  File "/Users/carla/opt/anaconda3/envs/DjangoEnv_PAS/lib/python3.9/site-packages/django_crontab/crontab.py", line 126, in run_job
    job = self.__get_job_by_hash(job_hash)
  File "/Users/carla/opt/anaconda3/envs/DjangoEnv_PAS/lib/python3.9/site-packages/django_crontab/crontab.py", line 171, in __get_job_by_hash
    raise RuntimeError(
RuntimeError: No job with hash 7a60db453bdc699323c7feb3b5be04ca found. It seems the crontab is out of sync with your settings.CRONJOBS. Run "python manage.py crontab add" again to resolve this issue!
Traceback (most recent call last):
  File "/Users/carla/Documents/ITC-Tec/Ago-Dic22/SeguridadRedes_SistemasSoft/projectScss/Pagina-web/backend/manage.py", line 22, in <module>
    main()
  File "/Users/carla/Documents/ITC-Tec/Ago-Dic22/SeguridadRedes_SistemasSoft/projectScss/Pagina-web/backend/manage.py", line 18, in main
    execute_from_command_line(sys.argv)
  File "/Users/carla/opt/anaconda3/envs/DjangoEnv_PAS/lib/python3.9/site-packages/django/core/management/__init__.py", line 446, in execute_from_command_line
    utility.execute()
  File "/Users/carla/opt/anaconda3/envs/DjangoEnv_PAS/lib/python3.9/site-packages/django/core/management/__init__.py", line 440, in execute
    self.fetch_command(subcommand).run_from_argv(self.argv)
  File "/Users/carla/opt/anaconda3/envs/DjangoEnv_PAS/lib/python3.9/site-packages/django/core/management/base.py", line 414, in run_from_argv
    self.execute(*args, **cmd_options)
  File "/Users/carla/opt/anaconda3/envs/DjangoEnv_PAS/lib/python3.9/site-packages/django/core/management/base.py", line 460, in execute
    output = self.handle(*args, **options)
  File "/Users/carla/opt/anaconda3/envs/DjangoEnv_PAS/lib/python3.9/site-packages/django_crontab/management/commands/crontab.py", line 29, in handle
    Crontab().run_job(options['jobhash'])
  File "/Users/carla/opt/anaconda3/envs/DjangoEnv_PAS/lib/python3.9/site-packages/django_crontab/crontab.py", line 126, in run_job
    job = self.__get_job_by_hash(job_hash)
  File "/Users/carla/opt/anaconda3/envs/DjangoEnv_PAS/lib/python3.9/site-packages/django_crontab/crontab.py", line 171, in __get_job_by_hash
    raise RuntimeError(
RuntimeError: No job with hash 7a60db453bdc699323c7feb3b5be04ca found. It seems the crontab is out of sync with your settings.CRONJOBS. Run "python manage.py crontab add" again to resolve this issue!
Traceback (most recent call last):
  File "/Users/carla/Documents/ITC-Tec/Ago-Dic22/SeguridadRedes_SistemasSoft/projectScss/Pagina-web/backend/manage.py", line 22, in <module>
    main()
  File "/Users/carla/Documents/ITC-Tec/Ago-Dic22/SeguridadRedes_SistemasSoft/projectScss/Pagina-web/backend/manage.py", line 18, in main
    execute_from_command_line(sys.argv)
  File "/Users/carla/opt/anaconda3/envs/DjangoEnv_PAS/lib/python3.9/site-packages/django/core/management/__init__.py", line 446, in execute_from_command_line
    utility.execute()
  File "/Users/carla/opt/anaconda3/envs/DjangoEnv_PAS/lib/python3.9/site-packages/django/core/management/__init__.py", line 440, in execute
    self.fetch_command(subcommand).run_from_argv(self.argv)
  File "/Users/carla/opt/anaconda3/envs/DjangoEnv_PAS/lib/python3.9/site-packages/django/core/management/base.py", line 414, in run_from_argv
    self.execute(*args, **cmd_options)
  File "/Users/carla/opt/anaconda3/envs/DjangoEnv_PAS/lib/python3.9/site-packages/django/core/management/base.py", line 460, in execute
    output = self.handle(*args, **options)
  File "/Users/carla/opt/anaconda3/envs/DjangoEnv_PAS/lib/python3.9/site-packages/django_crontab/management/commands/crontab.py", line 29, in handle
    Crontab().run_job(options['jobhash'])
  File "/Users/carla/opt/anaconda3/envs/DjangoEnv_PAS/lib/python3.9/site-packages/django_crontab/crontab.py", line 126, in run_job
    job = self.__get_job_by_hash(job_hash)
  File "/Users/carla/opt/anaconda3/envs/DjangoEnv_PAS/lib/python3.9/site-packages/django_crontab/crontab.py", line 171, in __get_job_by_hash
    raise RuntimeError(
RuntimeError: No job with hash 7a60db453bdc699323c7feb3b5be04ca found. It seems the crontab is out of sync with your settings.CRONJOBS. Run "python manage.py crontab add" again to resolve this issue!
Traceback (most recent call last):
  File "/Users/carla/Documents/ITC-Tec/Ago-Dic22/SeguridadRedes_SistemasSoft/projectScss/Pagina-web/backend/manage.py", line 22, in <module>
    main()
  File "/Users/carla/Documents/ITC-Tec/Ago-Dic22/SeguridadRedes_SistemasSoft/projectScss/Pagina-web/backend/manage.py", line 18, in main
    execute_from_command_line(sys.argv)
  File "/Users/carla/opt/anaconda3/envs/DjangoEnv_PAS/lib/python3.9/site-packages/django/core/management/__init__.py", line 446, in execute_from_command_line
    utility.execute()
  File "/Users/carla/opt/anaconda3/envs/DjangoEnv_PAS/lib/python3.9/site-packages/django/core/management/__init__.py", line 440, in execute
    self.fetch_command(subcommand).run_from_argv(self.argv)
  File "/Users/carla/opt/anaconda3/envs/DjangoEnv_PAS/lib/python3.9/site-packages/django/core/management/base.py", line 414, in run_from_argv
    self.execute(*args, **cmd_options)
  File "/Users/carla/opt/anaconda3/envs/DjangoEnv_PAS/lib/python3.9/site-packages/django/core/management/base.py", line 460, in execute
    output = self.handle(*args, **options)
  File "/Users/carla/opt/anaconda3/envs/DjangoEnv_PAS/lib/python3.9/site-packages/django_crontab/management/commands/crontab.py", line 29, in handle
    Crontab().run_job(options['jobhash'])
  File "/Users/carla/opt/anaconda3/envs/DjangoEnv_PAS/lib/python3.9/site-packages/django_crontab/crontab.py", line 126, in run_job
    job = self.__get_job_by_hash(job_hash)
  File "/Users/carla/opt/anaconda3/envs/DjangoEnv_PAS/lib/python3.9/site-packages/django_crontab/crontab.py", line 171, in __get_job_by_hash
    raise RuntimeError(
RuntimeError: No job with hash 7a60db453bdc699323c7feb3b5be04ca found. It seems the crontab is out of sync with your settings.CRONJOBS. Run "python manage.py crontab add" again to resolve this issue!
Traceback (most recent call last):
  File "/Users/carla/Documents/ITC-Tec/Ago-Dic22/SeguridadRedes_SistemasSoft/projectScss/Pagina-web/backend/manage.py", line 22, in <module>
    main()
  File "/Users/carla/Documents/ITC-Tec/Ago-Dic22/SeguridadRedes_SistemasSoft/projectScss/Pagina-web/backend/manage.py", line 18, in main
    execute_from_command_line(sys.argv)
  File "/Users/carla/opt/anaconda3/envs/DjangoEnv_PAS/lib/python3.9/site-packages/django/core/management/__init__.py", line 446, in execute_from_command_line
    utility.execute()
  File "/Users/carla/opt/anaconda3/envs/DjangoEnv_PAS/lib/python3.9/site-packages/django/core/management/__init__.py", line 440, in execute
    self.fetch_command(subcommand).run_from_argv(self.argv)
  File "/Users/carla/opt/anaconda3/envs/DjangoEnv_PAS/lib/python3.9/site-packages/django/core/management/base.py", line 414, in run_from_argv
    self.execute(*args, **cmd_options)
  File "/Users/carla/opt/anaconda3/envs/DjangoEnv_PAS/lib/python3.9/site-packages/django/core/management/base.py", line 460, in execute
    output = self.handle(*args, **options)
  File "/Users/carla/opt/anaconda3/envs/DjangoEnv_PAS/lib/python3.9/site-packages/django_crontab/management/commands/crontab.py", line 29, in handle
    Crontab().run_job(options['jobhash'])
  File "/Users/carla/opt/anaconda3/envs/DjangoEnv_PAS/lib/python3.9/site-packages/django_crontab/crontab.py", line 126, in run_job
    job = self.__get_job_by_hash(job_hash)
  File "/Users/carla/opt/anaconda3/envs/DjangoEnv_PAS/lib/python3.9/site-packages/django_crontab/crontab.py", line 171, in __get_job_by_hash
    raise RuntimeError(
RuntimeError: No job with hash 7a60db453bdc699323c7feb3b5be04ca found. It seems the crontab is out of sync with your settings.CRONJOBS. Run "python manage.py crontab add" again to resolve this issue!
Traceback (most recent call last):
  File "/Users/carla/Documents/ITC-Tec/Ago-Dic22/SeguridadRedes_SistemasSoft/projectScss/Pagina-web/backend/manage.py", line 22, in <module>
    main()
  File "/Users/carla/Documents/ITC-Tec/Ago-Dic22/SeguridadRedes_SistemasSoft/projectScss/Pagina-web/backend/manage.py", line 18, in main
    execute_from_command_line(sys.argv)
  File "/Users/carla/opt/anaconda3/envs/DjangoEnv_PAS/lib/python3.9/site-packages/django/core/management/__init__.py", line 446, in execute_from_command_line
    utility.execute()
  File "/Users/carla/opt/anaconda3/envs/DjangoEnv_PAS/lib/python3.9/site-packages/django/core/management/__init__.py", line 440, in execute
    self.fetch_command(subcommand).run_from_argv(self.argv)
  File "/Users/carla/opt/anaconda3/envs/DjangoEnv_PAS/lib/python3.9/site-packages/django/core/management/base.py", line 414, in run_from_argv
    self.execute(*args, **cmd_options)
  File "/Users/carla/opt/anaconda3/envs/DjangoEnv_PAS/lib/python3.9/site-packages/django/core/management/base.py", line 460, in execute
    output = self.handle(*args, **options)
  File "/Users/carla/opt/anaconda3/envs/DjangoEnv_PAS/lib/python3.9/site-packages/django_crontab/management/commands/crontab.py", line 29, in handle
    Crontab().run_job(options['jobhash'])
  File "/Users/carla/opt/anaconda3/envs/DjangoEnv_PAS/lib/python3.9/site-packages/django_crontab/crontab.py", line 126, in run_job
    job = self.__get_job_by_hash(job_hash)
  File "/Users/carla/opt/anaconda3/envs/DjangoEnv_PAS/lib/python3.9/site-packages/django_crontab/crontab.py", line 171, in __get_job_by_hash
    raise RuntimeError(
RuntimeError: No job with hash 7a60db453bdc699323c7feb3b5be04ca found. It seems the crontab is out of sync with your settings.CRONJOBS. Run "python manage.py crontab add" again to resolve this issue!
Traceback (most recent call last):
  File "/Users/carla/Documents/ITC-Tec/Ago-Dic22/SeguridadRedes_SistemasSoft/projectScss/Pagina-web/backend/manage.py", line 22, in <module>
    main()
  File "/Users/carla/Documents/ITC-Tec/Ago-Dic22/SeguridadRedes_SistemasSoft/projectScss/Pagina-web/backend/manage.py", line 18, in main
    execute_from_command_line(sys.argv)
  File "/Users/carla/opt/anaconda3/envs/DjangoEnv_PAS/lib/python3.9/site-packages/django/core/management/__init__.py", line 446, in execute_from_command_line
    utility.execute()
  File "/Users/carla/opt/anaconda3/envs/DjangoEnv_PAS/lib/python3.9/site-packages/django/core/management/__init__.py", line 440, in execute
    self.fetch_command(subcommand).run_from_argv(self.argv)
  File "/Users/carla/opt/anaconda3/envs/DjangoEnv_PAS/lib/python3.9/site-packages/django/core/management/base.py", line 414, in run_from_argv
    self.execute(*args, **cmd_options)
  File "/Users/carla/opt/anaconda3/envs/DjangoEnv_PAS/lib/python3.9/site-packages/django/core/management/base.py", line 460, in execute
    output = self.handle(*args, **options)
  File "/Users/carla/opt/anaconda3/envs/DjangoEnv_PAS/lib/python3.9/site-packages/django_crontab/management/commands/crontab.py", line 29, in handle
    Crontab().run_job(options['jobhash'])
  File "/Users/carla/opt/anaconda3/envs/DjangoEnv_PAS/lib/python3.9/site-packages/django_crontab/crontab.py", line 126, in run_job
    job = self.__get_job_by_hash(job_hash)
  File "/Users/carla/opt/anaconda3/envs/DjangoEnv_PAS/lib/python3.9/site-packages/django_crontab/crontab.py", line 171, in __get_job_by_hash
    raise RuntimeError(
RuntimeError: No job with hash 7a60db453bdc699323c7feb3b5be04ca found. It seems the crontab is out of sync with your settings.CRONJOBS. Run "python manage.py crontab add" again to resolve this issue!
Traceback (most recent call last):
  File "/Users/carla/Documents/ITC-Tec/Ago-Dic22/SeguridadRedes_SistemasSoft/projectScss/Pagina-web/backend/manage.py", line 22, in <module>
    main()
  File "/Users/carla/Documents/ITC-Tec/Ago-Dic22/SeguridadRedes_SistemasSoft/projectScss/Pagina-web/backend/manage.py", line 18, in main
    execute_from_command_line(sys.argv)
  File "/Users/carla/opt/anaconda3/envs/DjangoEnv_PAS/lib/python3.9/site-packages/django/core/management/__init__.py", line 446, in execute_from_command_line
    utility.execute()
  File "/Users/carla/opt/anaconda3/envs/DjangoEnv_PAS/lib/python3.9/site-packages/django/core/management/__init__.py", line 440, in execute
    self.fetch_command(subcommand).run_from_argv(self.argv)
  File "/Users/carla/opt/anaconda3/envs/DjangoEnv_PAS/lib/python3.9/site-packages/django/core/management/base.py", line 414, in run_from_argv
    self.execute(*args, **cmd_options)
  File "/Users/carla/opt/anaconda3/envs/DjangoEnv_PAS/lib/python3.9/site-packages/django/core/management/base.py", line 460, in execute
    output = self.handle(*args, **options)
  File "/Users/carla/opt/anaconda3/envs/DjangoEnv_PAS/lib/python3.9/site-packages/django_crontab/management/commands/crontab.py", line 29, in handle
    Crontab().run_job(options['jobhash'])
  File "/Users/carla/opt/anaconda3/envs/DjangoEnv_PAS/lib/python3.9/site-packages/django_crontab/crontab.py", line 126, in run_job
    job = self.__get_job_by_hash(job_hash)
  File "/Users/carla/opt/anaconda3/envs/DjangoEnv_PAS/lib/python3.9/site-packages/django_crontab/crontab.py", line 171, in __get_job_by_hash
    raise RuntimeError(
RuntimeError: No job with hash 7a60db453bdc699323c7feb3b5be04ca found. It seems the crontab is out of sync with your settings.CRONJOBS. Run "python manage.py crontab add" again to resolve this issue!
Traceback (most recent call last):
  File "/Users/carla/Documents/ITC-Tec/Ago-Dic22/SeguridadRedes_SistemasSoft/projectScss/Pagina-web/backend/manage.py", line 22, in <module>
    main()
  File "/Users/carla/Documents/ITC-Tec/Ago-Dic22/SeguridadRedes_SistemasSoft/projectScss/Pagina-web/backend/manage.py", line 18, in main
    execute_from_command_line(sys.argv)
  File "/Users/carla/opt/anaconda3/envs/DjangoEnv_PAS/lib/python3.9/site-packages/django/core/management/__init__.py", line 446, in execute_from_command_line
    utility.execute()
  File "/Users/carla/opt/anaconda3/envs/DjangoEnv_PAS/lib/python3.9/site-packages/django/core/management/__init__.py", line 440, in execute
    self.fetch_command(subcommand).run_from_argv(self.argv)
  File "/Users/carla/opt/anaconda3/envs/DjangoEnv_PAS/lib/python3.9/site-packages/django/core/management/base.py", line 414, in run_from_argv
    self.execute(*args, **cmd_options)
  File "/Users/carla/opt/anaconda3/envs/DjangoEnv_PAS/lib/python3.9/site-packages/django/core/management/base.py", line 460, in execute
    output = self.handle(*args, **options)
  File "/Users/carla/opt/anaconda3/envs/DjangoEnv_PAS/lib/python3.9/site-packages/django_crontab/management/commands/crontab.py", line 29, in handle
    Crontab().run_job(options['jobhash'])
  File "/Users/carla/opt/anaconda3/envs/DjangoEnv_PAS/lib/python3.9/site-packages/django_crontab/crontab.py", line 126, in run_job
    job = self.__get_job_by_hash(job_hash)
  File "/Users/carla/opt/anaconda3/envs/DjangoEnv_PAS/lib/python3.9/site-packages/django_crontab/crontab.py", line 171, in __get_job_by_hash
    raise RuntimeError(
RuntimeError: No job with hash 7a60db453bdc699323c7feb3b5be04ca found. It seems the crontab is out of sync with your settings.CRONJOBS. Run "python manage.py crontab add" again to resolve this issue!
Traceback (most recent call last):
  File "/Users/carla/Documents/ITC-Tec/Ago-Dic22/SeguridadRedes_SistemasSoft/projectScss/Pagina-web/backend/manage.py", line 22, in <module>
    main()
  File "/Users/carla/Documents/ITC-Tec/Ago-Dic22/SeguridadRedes_SistemasSoft/projectScss/Pagina-web/backend/manage.py", line 18, in main
    execute_from_command_line(sys.argv)
  File "/Users/carla/opt/anaconda3/envs/DjangoEnv_PAS/lib/python3.9/site-packages/django/core/management/__init__.py", line 446, in execute_from_command_line
    utility.execute()
  File "/Users/carla/opt/anaconda3/envs/DjangoEnv_PAS/lib/python3.9/site-packages/django/core/management/__init__.py", line 440, in execute
    self.fetch_command(subcommand).run_from_argv(self.argv)
  File "/Users/carla/opt/anaconda3/envs/DjangoEnv_PAS/lib/python3.9/site-packages/django/core/management/base.py", line 414, in run_from_argv
    self.execute(*args, **cmd_options)
  File "/Users/carla/opt/anaconda3/envs/DjangoEnv_PAS/lib/python3.9/site-packages/django/core/management/base.py", line 460, in execute
    output = self.handle(*args, **options)
  File "/Users/carla/opt/anaconda3/envs/DjangoEnv_PAS/lib/python3.9/site-packages/django_crontab/management/commands/crontab.py", line 29, in handle
    Crontab().run_job(options['jobhash'])
  File "/Users/carla/opt/anaconda3/envs/DjangoEnv_PAS/lib/python3.9/site-packages/django_crontab/crontab.py", line 126, in run_job
    job = self.__get_job_by_hash(job_hash)
  File "/Users/carla/opt/anaconda3/envs/DjangoEnv_PAS/lib/python3.9/site-packages/django_crontab/crontab.py", line 171, in __get_job_by_hash
    raise RuntimeError(
RuntimeError: No job with hash 7a60db453bdc699323c7feb3b5be04ca found. It seems the crontab is out of sync with your settings.CRONJOBS. Run "python manage.py crontab add" again to resolve this issue!
Traceback (most recent call last):
  File "/Users/carla/Documents/ITC-Tec/Ago-Dic22/SeguridadRedes_SistemasSoft/projectScss/Pagina-web/backend/manage.py", line 22, in <module>
    main()
  File "/Users/carla/Documents/ITC-Tec/Ago-Dic22/SeguridadRedes_SistemasSoft/projectScss/Pagina-web/backend/manage.py", line 18, in main
    execute_from_command_line(sys.argv)
  File "/Users/carla/opt/anaconda3/envs/DjangoEnv_PAS/lib/python3.9/site-packages/django/core/management/__init__.py", line 446, in execute_from_command_line
    utility.execute()
  File "/Users/carla/opt/anaconda3/envs/DjangoEnv_PAS/lib/python3.9/site-packages/django/core/management/__init__.py", line 440, in execute
    self.fetch_command(subcommand).run_from_argv(self.argv)
  File "/Users/carla/opt/anaconda3/envs/DjangoEnv_PAS/lib/python3.9/site-packages/django/core/management/base.py", line 414, in run_from_argv
    self.execute(*args, **cmd_options)
  File "/Users/carla/opt/anaconda3/envs/DjangoEnv_PAS/lib/python3.9/site-packages/django/core/management/base.py", line 460, in execute
    output = self.handle(*args, **options)
  File "/Users/carla/opt/anaconda3/envs/DjangoEnv_PAS/lib/python3.9/site-packages/django_crontab/management/commands/crontab.py", line 29, in handle
    Crontab().run_job(options['jobhash'])
  File "/Users/carla/opt/anaconda3/envs/DjangoEnv_PAS/lib/python3.9/site-packages/django_crontab/crontab.py", line 126, in run_job
    job = self.__get_job_by_hash(job_hash)
  File "/Users/carla/opt/anaconda3/envs/DjangoEnv_PAS/lib/python3.9/site-packages/django_crontab/crontab.py", line 171, in __get_job_by_hash
    raise RuntimeError(
RuntimeError: No job with hash 7a60db453bdc699323c7feb3b5be04ca found. It seems the crontab is out of sync with your settings.CRONJOBS. Run "python manage.py crontab add" again to resolve this issue!
Traceback (most recent call last):
  File "/Users/carla/Documents/ITC-Tec/Ago-Dic22/SeguridadRedes_SistemasSoft/projectScss/Pagina-web/backend/manage.py", line 22, in <module>
    main()
  File "/Users/carla/Documents/ITC-Tec/Ago-Dic22/SeguridadRedes_SistemasSoft/projectScss/Pagina-web/backend/manage.py", line 18, in main
    execute_from_command_line(sys.argv)
  File "/Users/carla/opt/anaconda3/envs/DjangoEnv_PAS/lib/python3.9/site-packages/django/core/management/__init__.py", line 446, in execute_from_command_line
    utility.execute()
  File "/Users/carla/opt/anaconda3/envs/DjangoEnv_PAS/lib/python3.9/site-packages/django/core/management/__init__.py", line 440, in execute
    self.fetch_command(subcommand).run_from_argv(self.argv)
  File "/Users/carla/opt/anaconda3/envs/DjangoEnv_PAS/lib/python3.9/site-packages/django/core/management/base.py", line 414, in run_from_argv
    self.execute(*args, **cmd_options)
  File "/Users/carla/opt/anaconda3/envs/DjangoEnv_PAS/lib/python3.9/site-packages/django/core/management/base.py", line 460, in execute
    output = self.handle(*args, **options)
  File "/Users/carla/opt/anaconda3/envs/DjangoEnv_PAS/lib/python3.9/site-packages/django_crontab/management/commands/crontab.py", line 29, in handle
    Crontab().run_job(options['jobhash'])
  File "/Users/carla/opt/anaconda3/envs/DjangoEnv_PAS/lib/python3.9/site-packages/django_crontab/crontab.py", line 126, in run_job
    job = self.__get_job_by_hash(job_hash)
  File "/Users/carla/opt/anaconda3/envs/DjangoEnv_PAS/lib/python3.9/site-packages/django_crontab/crontab.py", line 171, in __get_job_by_hash
    raise RuntimeError(
RuntimeError: No job with hash 7a60db453bdc699323c7feb3b5be04ca found. It seems the crontab is out of sync with your settings.CRONJOBS. Run "python manage.py crontab add" again to resolve this issue!
Traceback (most recent call last):
  File "/Users/carla/Documents/ITC-Tec/Ago-Dic22/SeguridadRedes_SistemasSoft/projectScss/Pagina-web/backend/manage.py", line 22, in <module>
    main()
  File "/Users/carla/Documents/ITC-Tec/Ago-Dic22/SeguridadRedes_SistemasSoft/projectScss/Pagina-web/backend/manage.py", line 18, in main
    execute_from_command_line(sys.argv)
  File "/Users/carla/opt/anaconda3/envs/DjangoEnv_PAS/lib/python3.9/site-packages/django/core/management/__init__.py", line 446, in execute_from_command_line
    utility.execute()
  File "/Users/carla/opt/anaconda3/envs/DjangoEnv_PAS/lib/python3.9/site-packages/django/core/management/__init__.py", line 440, in execute
    self.fetch_command(subcommand).run_from_argv(self.argv)
  File "/Users/carla/opt/anaconda3/envs/DjangoEnv_PAS/lib/python3.9/site-packages/django/core/management/base.py", line 414, in run_from_argv
    self.execute(*args, **cmd_options)
  File "/Users/carla/opt/anaconda3/envs/DjangoEnv_PAS/lib/python3.9/site-packages/django/core/management/base.py", line 460, in execute
    output = self.handle(*args, **options)
  File "/Users/carla/opt/anaconda3/envs/DjangoEnv_PAS/lib/python3.9/site-packages/django_crontab/management/commands/crontab.py", line 29, in handle
    Crontab().run_job(options['jobhash'])
  File "/Users/carla/opt/anaconda3/envs/DjangoEnv_PAS/lib/python3.9/site-packages/django_crontab/crontab.py", line 126, in run_job
    job = self.__get_job_by_hash(job_hash)
  File "/Users/carla/opt/anaconda3/envs/DjangoEnv_PAS/lib/python3.9/site-packages/django_crontab/crontab.py", line 171, in __get_job_by_hash
    raise RuntimeError(
RuntimeError: No job with hash 7a60db453bdc699323c7feb3b5be04ca found. It seems the crontab is out of sync with your settings.CRONJOBS. Run "python manage.py crontab add" again to resolve this issue!
Traceback (most recent call last):
  File "/Users/carla/Documents/ITC-Tec/Ago-Dic22/SeguridadRedes_SistemasSoft/projectScss/Pagina-web/backend/manage.py", line 22, in <module>
    main()
  File "/Users/carla/Documents/ITC-Tec/Ago-Dic22/SeguridadRedes_SistemasSoft/projectScss/Pagina-web/backend/manage.py", line 18, in main
    execute_from_command_line(sys.argv)
  File "/Users/carla/opt/anaconda3/envs/DjangoEnv_PAS/lib/python3.9/site-packages/django/core/management/__init__.py", line 446, in execute_from_command_line
    utility.execute()
  File "/Users/carla/opt/anaconda3/envs/DjangoEnv_PAS/lib/python3.9/site-packages/django/core/management/__init__.py", line 440, in execute
    self.fetch_command(subcommand).run_from_argv(self.argv)
  File "/Users/carla/opt/anaconda3/envs/DjangoEnv_PAS/lib/python3.9/site-packages/django/core/management/base.py", line 414, in run_from_argv
    self.execute(*args, **cmd_options)
  File "/Users/carla/opt/anaconda3/envs/DjangoEnv_PAS/lib/python3.9/site-packages/django/core/management/base.py", line 460, in execute
    output = self.handle(*args, **options)
  File "/Users/carla/opt/anaconda3/envs/DjangoEnv_PAS/lib/python3.9/site-packages/django_crontab/management/commands/crontab.py", line 29, in handle
    Crontab().run_job(options['jobhash'])
  File "/Users/carla/opt/anaconda3/envs/DjangoEnv_PAS/lib/python3.9/site-packages/django_crontab/crontab.py", line 126, in run_job
    job = self.__get_job_by_hash(job_hash)
  File "/Users/carla/opt/anaconda3/envs/DjangoEnv_PAS/lib/python3.9/site-packages/django_crontab/crontab.py", line 171, in __get_job_by_hash
    raise RuntimeError(
RuntimeError: No job with hash 7a60db453bdc699323c7feb3b5be04ca found. It seems the crontab is out of sync with your settings.CRONJOBS. Run "python manage.py crontab add" again to resolve this issue!
Traceback (most recent call last):
  File "/Users/carla/Documents/ITC-Tec/Ago-Dic22/SeguridadRedes_SistemasSoft/projectScss/Pagina-web/backend/manage.py", line 22, in <module>
    main()
  File "/Users/carla/Documents/ITC-Tec/Ago-Dic22/SeguridadRedes_SistemasSoft/projectScss/Pagina-web/backend/manage.py", line 18, in main
    execute_from_command_line(sys.argv)
  File "/Users/carla/opt/anaconda3/envs/DjangoEnv_PAS/lib/python3.9/site-packages/django/core/management/__init__.py", line 446, in execute_from_command_line
    utility.execute()
  File "/Users/carla/opt/anaconda3/envs/DjangoEnv_PAS/lib/python3.9/site-packages/django/core/management/__init__.py", line 440, in execute
    self.fetch_command(subcommand).run_from_argv(self.argv)
  File "/Users/carla/opt/anaconda3/envs/DjangoEnv_PAS/lib/python3.9/site-packages/django/core/management/base.py", line 414, in run_from_argv
    self.execute(*args, **cmd_options)
  File "/Users/carla/opt/anaconda3/envs/DjangoEnv_PAS/lib/python3.9/site-packages/django/core/management/base.py", line 460, in execute
    output = self.handle(*args, **options)
  File "/Users/carla/opt/anaconda3/envs/DjangoEnv_PAS/lib/python3.9/site-packages/django_crontab/management/commands/crontab.py", line 29, in handle
    Crontab().run_job(options['jobhash'])
  File "/Users/carla/opt/anaconda3/envs/DjangoEnv_PAS/lib/python3.9/site-packages/django_crontab/crontab.py", line 126, in run_job
    job = self.__get_job_by_hash(job_hash)
  File "/Users/carla/opt/anaconda3/envs/DjangoEnv_PAS/lib/python3.9/site-packages/django_crontab/crontab.py", line 171, in __get_job_by_hash
    raise RuntimeError(
RuntimeError: No job with hash 7a60db453bdc699323c7feb3b5be04ca found. It seems the crontab is out of sync with your settings.CRONJOBS. Run "python manage.py crontab add" again to resolve this issue!
Traceback (most recent call last):
  File "/Users/carla/Documents/ITC-Tec/Ago-Dic22/SeguridadRedes_SistemasSoft/projectScss/Pagina-web/backend/manage.py", line 22, in <module>
    main()
  File "/Users/carla/Documents/ITC-Tec/Ago-Dic22/SeguridadRedes_SistemasSoft/projectScss/Pagina-web/backend/manage.py", line 18, in main
    execute_from_command_line(sys.argv)
  File "/Users/carla/opt/anaconda3/envs/DjangoEnv_PAS/lib/python3.9/site-packages/django/core/management/__init__.py", line 446, in execute_from_command_line
    utility.execute()
  File "/Users/carla/opt/anaconda3/envs/DjangoEnv_PAS/lib/python3.9/site-packages/django/core/management/__init__.py", line 440, in execute
    self.fetch_command(subcommand).run_from_argv(self.argv)
  File "/Users/carla/opt/anaconda3/envs/DjangoEnv_PAS/lib/python3.9/site-packages/django/core/management/base.py", line 414, in run_from_argv
    self.execute(*args, **cmd_options)
  File "/Users/carla/opt/anaconda3/envs/DjangoEnv_PAS/lib/python3.9/site-packages/django/core/management/base.py", line 460, in execute
    output = self.handle(*args, **options)
  File "/Users/carla/opt/anaconda3/envs/DjangoEnv_PAS/lib/python3.9/site-packages/django_crontab/management/commands/crontab.py", line 29, in handle
    Crontab().run_job(options['jobhash'])
  File "/Users/carla/opt/anaconda3/envs/DjangoEnv_PAS/lib/python3.9/site-packages/django_crontab/crontab.py", line 126, in run_job
    job = self.__get_job_by_hash(job_hash)
  File "/Users/carla/opt/anaconda3/envs/DjangoEnv_PAS/lib/python3.9/site-packages/django_crontab/crontab.py", line 171, in __get_job_by_hash
    raise RuntimeError(
RuntimeError: No job with hash 7a60db453bdc699323c7feb3b5be04ca found. It seems the crontab is out of sync with your settings.CRONJOBS. Run "python manage.py crontab add" again to resolve this issue!
Traceback (most recent call last):
  File "/Users/carla/Documents/ITC-Tec/Ago-Dic22/SeguridadRedes_SistemasSoft/projectScss/Pagina-web/backend/manage.py", line 22, in <module>
    main()
  File "/Users/carla/Documents/ITC-Tec/Ago-Dic22/SeguridadRedes_SistemasSoft/projectScss/Pagina-web/backend/manage.py", line 18, in main
    execute_from_command_line(sys.argv)
  File "/Users/carla/opt/anaconda3/envs/DjangoEnv_PAS/lib/python3.9/site-packages/django/core/management/__init__.py", line 446, in execute_from_command_line
    utility.execute()
  File "/Users/carla/opt/anaconda3/envs/DjangoEnv_PAS/lib/python3.9/site-packages/django/core/management/__init__.py", line 440, in execute
    self.fetch_command(subcommand).run_from_argv(self.argv)
  File "/Users/carla/opt/anaconda3/envs/DjangoEnv_PAS/lib/python3.9/site-packages/django/core/management/base.py", line 414, in run_from_argv
    self.execute(*args, **cmd_options)
  File "/Users/carla/opt/anaconda3/envs/DjangoEnv_PAS/lib/python3.9/site-packages/django/core/management/base.py", line 460, in execute
    output = self.handle(*args, **options)
  File "/Users/carla/opt/anaconda3/envs/DjangoEnv_PAS/lib/python3.9/site-packages/django_crontab/management/commands/crontab.py", line 29, in handle
    Crontab().run_job(options['jobhash'])
  File "/Users/carla/opt/anaconda3/envs/DjangoEnv_PAS/lib/python3.9/site-packages/django_crontab/crontab.py", line 126, in run_job
    job = self.__get_job_by_hash(job_hash)
  File "/Users/carla/opt/anaconda3/envs/DjangoEnv_PAS/lib/python3.9/site-packages/django_crontab/crontab.py", line 171, in __get_job_by_hash
    raise RuntimeError(
RuntimeError: No job with hash 7a60db453bdc699323c7feb3b5be04ca found. It seems the crontab is out of sync with your settings.CRONJOBS. Run "python manage.py crontab add" again to resolve this issue!
Traceback (most recent call last):
  File "/Users/carla/Documents/ITC-Tec/Ago-Dic22/SeguridadRedes_SistemasSoft/projectScss/Pagina-web/backend/manage.py", line 22, in <module>
    main()
  File "/Users/carla/Documents/ITC-Tec/Ago-Dic22/SeguridadRedes_SistemasSoft/projectScss/Pagina-web/backend/manage.py", line 18, in main
    execute_from_command_line(sys.argv)
  File "/Users/carla/opt/anaconda3/envs/DjangoEnv_PAS/lib/python3.9/site-packages/django/core/management/__init__.py", line 446, in execute_from_command_line
    utility.execute()
  File "/Users/carla/opt/anaconda3/envs/DjangoEnv_PAS/lib/python3.9/site-packages/django/core/management/__init__.py", line 440, in execute
    self.fetch_command(subcommand).run_from_argv(self.argv)
  File "/Users/carla/opt/anaconda3/envs/DjangoEnv_PAS/lib/python3.9/site-packages/django/core/management/base.py", line 414, in run_from_argv
    self.execute(*args, **cmd_options)
  File "/Users/carla/opt/anaconda3/envs/DjangoEnv_PAS/lib/python3.9/site-packages/django/core/management/base.py", line 460, in execute
    output = self.handle(*args, **options)
  File "/Users/carla/opt/anaconda3/envs/DjangoEnv_PAS/lib/python3.9/site-packages/django_crontab/management/commands/crontab.py", line 29, in handle
    Crontab().run_job(options['jobhash'])
  File "/Users/carla/opt/anaconda3/envs/DjangoEnv_PAS/lib/python3.9/site-packages/django_crontab/crontab.py", line 126, in run_job
    job = self.__get_job_by_hash(job_hash)
  File "/Users/carla/opt/anaconda3/envs/DjangoEnv_PAS/lib/python3.9/site-packages/django_crontab/crontab.py", line 171, in __get_job_by_hash
    raise RuntimeError(
RuntimeError: No job with hash 7a60db453bdc699323c7feb3b5be04ca found. It seems the crontab is out of sync with your settings.CRONJOBS. Run "python manage.py crontab add" again to resolve this issue!
Traceback (most recent call last):
  File "/Users/carla/Documents/ITC-Tec/Ago-Dic22/SeguridadRedes_SistemasSoft/projectScss/Pagina-web/backend/manage.py", line 22, in <module>
    main()
  File "/Users/carla/Documents/ITC-Tec/Ago-Dic22/SeguridadRedes_SistemasSoft/projectScss/Pagina-web/backend/manage.py", line 18, in main
    execute_from_command_line(sys.argv)
  File "/Users/carla/opt/anaconda3/envs/DjangoEnv_PAS/lib/python3.9/site-packages/django/core/management/__init__.py", line 446, in execute_from_command_line
    utility.execute()
  File "/Users/carla/opt/anaconda3/envs/DjangoEnv_PAS/lib/python3.9/site-packages/django/core/management/__init__.py", line 440, in execute
    self.fetch_command(subcommand).run_from_argv(self.argv)
  File "/Users/carla/opt/anaconda3/envs/DjangoEnv_PAS/lib/python3.9/site-packages/django/core/management/base.py", line 414, in run_from_argv
    self.execute(*args, **cmd_options)
  File "/Users/carla/opt/anaconda3/envs/DjangoEnv_PAS/lib/python3.9/site-packages/django/core/management/base.py", line 460, in execute
    output = self.handle(*args, **options)
  File "/Users/carla/opt/anaconda3/envs/DjangoEnv_PAS/lib/python3.9/site-packages/django_crontab/management/commands/crontab.py", line 29, in handle
    Crontab().run_job(options['jobhash'])
  File "/Users/carla/opt/anaconda3/envs/DjangoEnv_PAS/lib/python3.9/site-packages/django_crontab/crontab.py", line 126, in run_job
    job = self.__get_job_by_hash(job_hash)
  File "/Users/carla/opt/anaconda3/envs/DjangoEnv_PAS/lib/python3.9/site-packages/django_crontab/crontab.py", line 171, in __get_job_by_hash
    raise RuntimeError(
RuntimeError: No job with hash 7a60db453bdc699323c7feb3b5be04ca found. It seems the crontab is out of sync with your settings.CRONJOBS. Run "python manage.py crontab add" again to resolve this issue!
Traceback (most recent call last):
  File "/Users/carla/Documents/ITC-Tec/Ago-Dic22/SeguridadRedes_SistemasSoft/projectScss/Pagina-web/backend/manage.py", line 22, in <module>
    main()
  File "/Users/carla/Documents/ITC-Tec/Ago-Dic22/SeguridadRedes_SistemasSoft/projectScss/Pagina-web/backend/manage.py", line 18, in main
    execute_from_command_line(sys.argv)
  File "/Users/carla/opt/anaconda3/envs/DjangoEnv_PAS/lib/python3.9/site-packages/django/core/management/__init__.py", line 446, in execute_from_command_line
    utility.execute()
  File "/Users/carla/opt/anaconda3/envs/DjangoEnv_PAS/lib/python3.9/site-packages/django/core/management/__init__.py", line 440, in execute
    self.fetch_command(subcommand).run_from_argv(self.argv)
  File "/Users/carla/opt/anaconda3/envs/DjangoEnv_PAS/lib/python3.9/site-packages/django/core/management/base.py", line 414, in run_from_argv
    self.execute(*args, **cmd_options)
  File "/Users/carla/opt/anaconda3/envs/DjangoEnv_PAS/lib/python3.9/site-packages/django/core/management/base.py", line 460, in execute
    output = self.handle(*args, **options)
  File "/Users/carla/opt/anaconda3/envs/DjangoEnv_PAS/lib/python3.9/site-packages/django_crontab/management/commands/crontab.py", line 29, in handle
    Crontab().run_job(options['jobhash'])
  File "/Users/carla/opt/anaconda3/envs/DjangoEnv_PAS/lib/python3.9/site-packages/django_crontab/crontab.py", line 126, in run_job
    job = self.__get_job_by_hash(job_hash)
  File "/Users/carla/opt/anaconda3/envs/DjangoEnv_PAS/lib/python3.9/site-packages/django_crontab/crontab.py", line 171, in __get_job_by_hash
    raise RuntimeError(
RuntimeError: No job with hash 7a60db453bdc699323c7feb3b5be04ca found. It seems the crontab is out of sync with your settings.CRONJOBS. Run "python manage.py crontab add" again to resolve this issue!
Traceback (most recent call last):
  File "/Users/carla/Documents/ITC-Tec/Ago-Dic22/SeguridadRedes_SistemasSoft/projectScss/Pagina-web/backend/manage.py", line 22, in <module>
    main()
  File "/Users/carla/Documents/ITC-Tec/Ago-Dic22/SeguridadRedes_SistemasSoft/projectScss/Pagina-web/backend/manage.py", line 18, in main
    execute_from_command_line(sys.argv)
  File "/Users/carla/opt/anaconda3/envs/DjangoEnv_PAS/lib/python3.9/site-packages/django/core/management/__init__.py", line 446, in execute_from_command_line
    utility.execute()
  File "/Users/carla/opt/anaconda3/envs/DjangoEnv_PAS/lib/python3.9/site-packages/django/core/management/__init__.py", line 440, in execute
    self.fetch_command(subcommand).run_from_argv(self.argv)
  File "/Users/carla/opt/anaconda3/envs/DjangoEnv_PAS/lib/python3.9/site-packages/django/core/management/base.py", line 414, in run_from_argv
    self.execute(*args, **cmd_options)
  File "/Users/carla/opt/anaconda3/envs/DjangoEnv_PAS/lib/python3.9/site-packages/django/core/management/base.py", line 460, in execute
    output = self.handle(*args, **options)
  File "/Users/carla/opt/anaconda3/envs/DjangoEnv_PAS/lib/python3.9/site-packages/django_crontab/management/commands/crontab.py", line 29, in handle
    Crontab().run_job(options['jobhash'])
  File "/Users/carla/opt/anaconda3/envs/DjangoEnv_PAS/lib/python3.9/site-packages/django_crontab/crontab.py", line 126, in run_job
    job = self.__get_job_by_hash(job_hash)
  File "/Users/carla/opt/anaconda3/envs/DjangoEnv_PAS/lib/python3.9/site-packages/django_crontab/crontab.py", line 171, in __get_job_by_hash
    raise RuntimeError(
RuntimeError: No job with hash 7a60db453bdc699323c7feb3b5be04ca found. It seems the crontab is out of sync with your settings.CRONJOBS. Run "python manage.py crontab add" again to resolve this issue!
Traceback (most recent call last):
  File "/Users/carla/Documents/ITC-Tec/Ago-Dic22/SeguridadRedes_SistemasSoft/projectScss/Pagina-web/backend/manage.py", line 22, in <module>
    main()
  File "/Users/carla/Documents/ITC-Tec/Ago-Dic22/SeguridadRedes_SistemasSoft/projectScss/Pagina-web/backend/manage.py", line 18, in main
    execute_from_command_line(sys.argv)
  File "/Users/carla/opt/anaconda3/envs/DjangoEnv_PAS/lib/python3.9/site-packages/django/core/management/__init__.py", line 446, in execute_from_command_line
    utility.execute()
  File "/Users/carla/opt/anaconda3/envs/DjangoEnv_PAS/lib/python3.9/site-packages/django/core/management/__init__.py", line 420, in execute
    django.setup()
  File "/Users/carla/opt/anaconda3/envs/DjangoEnv_PAS/lib/python3.9/site-packages/django/__init__.py", line 24, in setup
    apps.populate(settings.INSTALLED_APPS)
  File "/Users/carla/opt/anaconda3/envs/DjangoEnv_PAS/lib/python3.9/site-packages/django/apps/registry.py", line 93, in populate
    raise ImproperlyConfigured(
django.core.exceptions.ImproperlyConfigured: Application labels aren't unique, duplicates: staticfiles
Traceback (most recent call last):
  File "/Users/carla/Documents/ITC-Tec/Ago-Dic22/SeguridadRedes_SistemasSoft/projectScss/Pagina-web/backend/manage.py", line 22, in <module>
    main()
  File "/Users/carla/Documents/ITC-Tec/Ago-Dic22/SeguridadRedes_SistemasSoft/projectScss/Pagina-web/backend/manage.py", line 18, in main
    execute_from_command_line(sys.argv)
  File "/Users/carla/opt/anaconda3/envs/DjangoEnv_PAS/lib/python3.9/site-packages/django/core/management/__init__.py", line 446, in execute_from_command_line
    utility.execute()
  File "/Users/carla/opt/anaconda3/envs/DjangoEnv_PAS/lib/python3.9/site-packages/django/core/management/__init__.py", line 420, in execute
    django.setup()
  File "/Users/carla/opt/anaconda3/envs/DjangoEnv_PAS/lib/python3.9/site-packages/django/__init__.py", line 24, in setup
    apps.populate(settings.INSTALLED_APPS)
  File "/Users/carla/opt/anaconda3/envs/DjangoEnv_PAS/lib/python3.9/site-packages/django/apps/registry.py", line 93, in populate
    raise ImproperlyConfigured(
django.core.exceptions.ImproperlyConfigured: Application labels aren't unique, duplicates: staticfiles
Traceback (most recent call last):
  File "/Users/carla/Documents/ITC-Tec/Ago-Dic22/SeguridadRedes_SistemasSoft/projectScss/Pagina-web/backend/manage.py", line 22, in <module>
    main()
  File "/Users/carla/Documents/ITC-Tec/Ago-Dic22/SeguridadRedes_SistemasSoft/projectScss/Pagina-web/backend/manage.py", line 18, in main
    execute_from_command_line(sys.argv)
  File "/Users/carla/opt/anaconda3/envs/DjangoEnv_PAS/lib/python3.9/site-packages/django/core/management/__init__.py", line 446, in execute_from_command_line
    utility.execute()
  File "/Users/carla/opt/anaconda3/envs/DjangoEnv_PAS/lib/python3.9/site-packages/django/core/management/__init__.py", line 420, in execute
    django.setup()
  File "/Users/carla/opt/anaconda3/envs/DjangoEnv_PAS/lib/python3.9/site-packages/django/__init__.py", line 24, in setup
    apps.populate(settings.INSTALLED_APPS)
  File "/Users/carla/opt/anaconda3/envs/DjangoEnv_PAS/lib/python3.9/site-packages/django/apps/registry.py", line 93, in populate
    raise ImproperlyConfigured(
django.core.exceptions.ImproperlyConfigured: Application labels aren't unique, duplicates: staticfiles
Traceback (most recent call last):
  File "/Users/carla/Documents/ITC-Tec/Ago-Dic22/SeguridadRedes_SistemasSoft/projectScss/Pagina-web/backend/manage.py", line 22, in <module>
    main()
  File "/Users/carla/Documents/ITC-Tec/Ago-Dic22/SeguridadRedes_SistemasSoft/projectScss/Pagina-web/backend/manage.py", line 18, in main
    execute_from_command_line(sys.argv)
  File "/Users/carla/opt/anaconda3/envs/DjangoEnv_PAS/lib/python3.9/site-packages/django/core/management/__init__.py", line 446, in execute_from_command_line
    utility.execute()
  File "/Users/carla/opt/anaconda3/envs/DjangoEnv_PAS/lib/python3.9/site-packages/django/core/management/__init__.py", line 386, in execute
    settings.INSTALLED_APPS
  File "/Users/carla/opt/anaconda3/envs/DjangoEnv_PAS/lib/python3.9/site-packages/django/conf/__init__.py", line 87, in __getattr__
    self._setup(name)
  File "/Users/carla/opt/anaconda3/envs/DjangoEnv_PAS/lib/python3.9/site-packages/django/conf/__init__.py", line 74, in _setup
    self._wrapped = Settings(settings_module)
  File "/Users/carla/opt/anaconda3/envs/DjangoEnv_PAS/lib/python3.9/site-packages/django/conf/__init__.py", line 183, in __init__
    mod = importlib.import_module(self.SETTINGS_MODULE)
  File "/Users/carla/opt/anaconda3/envs/DjangoEnv_PAS/lib/python3.9/importlib/__init__.py", line 127, in import_module
    return _bootstrap._gcd_import(name[level:], package, level)
  File "<frozen importlib._bootstrap>", line 1030, in _gcd_import
  File "<frozen importlib._bootstrap>", line 1007, in _find_and_load
  File "<frozen importlib._bootstrap>", line 986, in _find_and_load_unlocked
  File "<frozen importlib._bootstrap>", line 680, in _load_unlocked
  File "<frozen importlib._bootstrap_external>", line 846, in exec_module
  File "<frozen importlib._bootstrap_external>", line 983, in get_code
  File "<frozen importlib._bootstrap_external>", line 913, in source_to_code
  File "<frozen importlib._bootstrap>", line 228, in _call_with_frames_removed
  File "/Users/carla/Documents/ITC-Tec/Ago-Dic22/SeguridadRedes_SistemasSoft/projectScss/Pagina-web/backend/backend/settings.py", line 28
    ALLOWED_HOSTS = [https://infinite-security.herokuapp.com/]
                          ^
SyntaxError: invalid syntax
Traceback (most recent call last):
  File "/Users/carla/Documents/ITC-Tec/Ago-Dic22/SeguridadRedes_SistemasSoft/projectScss/Pagina-web/backend/manage.py", line 22, in <module>
    main()
  File "/Users/carla/Documents/ITC-Tec/Ago-Dic22/SeguridadRedes_SistemasSoft/projectScss/Pagina-web/backend/manage.py", line 18, in main
    execute_from_command_line(sys.argv)
  File "/Users/carla/opt/anaconda3/envs/DjangoEnv_PAS/lib/python3.9/site-packages/django/core/management/__init__.py", line 446, in execute_from_command_line
    utility.execute()
  File "/Users/carla/opt/anaconda3/envs/DjangoEnv_PAS/lib/python3.9/site-packages/django/core/management/__init__.py", line 420, in execute
    django.setup()
  File "/Users/carla/opt/anaconda3/envs/DjangoEnv_PAS/lib/python3.9/site-packages/django/__init__.py", line 24, in setup
    apps.populate(settings.INSTALLED_APPS)
  File "/Users/carla/opt/anaconda3/envs/DjangoEnv_PAS/lib/python3.9/site-packages/django/apps/registry.py", line 93, in populate
    raise ImproperlyConfigured(
django.core.exceptions.ImproperlyConfigured: Application labels aren't unique, duplicates: staticfiles
Traceback (most recent call last):
  File "/Users/carla/Documents/ITC-Tec/Ago-Dic22/SeguridadRedes_SistemasSoft/projectScss/Pagina-web/backend/manage.py", line 22, in <module>
    main()
  File "/Users/carla/Documents/ITC-Tec/Ago-Dic22/SeguridadRedes_SistemasSoft/projectScss/Pagina-web/backend/manage.py", line 18, in main
    execute_from_command_line(sys.argv)
  File "/Users/carla/opt/anaconda3/envs/DjangoEnv_PAS/lib/python3.9/site-packages/django/core/management/__init__.py", line 446, in execute_from_command_line
    utility.execute()
  File "/Users/carla/opt/anaconda3/envs/DjangoEnv_PAS/lib/python3.9/site-packages/django/core/management/__init__.py", line 420, in execute
    django.setup()
  File "/Users/carla/opt/anaconda3/envs/DjangoEnv_PAS/lib/python3.9/site-packages/django/__init__.py", line 24, in setup
    apps.populate(settings.INSTALLED_APPS)
  File "/Users/carla/opt/anaconda3/envs/DjangoEnv_PAS/lib/python3.9/site-packages/django/apps/registry.py", line 93, in populate
    raise ImproperlyConfigured(
django.core.exceptions.ImproperlyConfigured: Application labels aren't unique, duplicates: staticfiles
Traceback (most recent call last):
  File "/Users/carla/Documents/ITC-Tec/Ago-Dic22/SeguridadRedes_SistemasSoft/projectScss/Pagina-web/backend/manage.py", line 22, in <module>
    main()
  File "/Users/carla/Documents/ITC-Tec/Ago-Dic22/SeguridadRedes_SistemasSoft/projectScss/Pagina-web/backend/manage.py", line 18, in main
    execute_from_command_line(sys.argv)
  File "/Users/carla/opt/anaconda3/envs/DjangoEnv_PAS/lib/python3.9/site-packages/django/core/management/__init__.py", line 446, in execute_from_command_line
    utility.execute()
  File "/Users/carla/opt/anaconda3/envs/DjangoEnv_PAS/lib/python3.9/site-packages/django/core/management/__init__.py", line 420, in execute
    django.setup()
  File "/Users/carla/opt/anaconda3/envs/DjangoEnv_PAS/lib/python3.9/site-packages/django/__init__.py", line 24, in setup
    apps.populate(settings.INSTALLED_APPS)
  File "/Users/carla/opt/anaconda3/envs/DjangoEnv_PAS/lib/python3.9/site-packages/django/apps/registry.py", line 93, in populate
    raise ImproperlyConfigured(
django.core.exceptions.ImproperlyConfigured: Application labels aren't unique, duplicates: staticfiles
